<mujoco>
    <worldbody>
        <!-- Large plane surface named 'ground_plane' -->
        <body name="ground_plane" pos="0 0 0">
            <geom type="plane" size="10 10 0.1" rgba="0.8 0.8 0.8 1"/>
        </body>
        
        <!-- Table-sized rectangular body placed 3m above the 'ground_plane' -->
        <body name="table" pos="0 0 3">
            <geom type="box" size="1 1.5 0.2" rgba="0.2 0.2 0.8 1"/>
            <freejoint/>

            <!-- Adding stalks at the corners of the table -->
            <!-- Front-left stalk -->
            <body name="stalk_front_left" pos="-1 -1.5 -0.8">
                <geom type="cylinder" size="0.05 1 0" rgba="0.5 0.5 0.5 1"/>
                <joint name="hinge_front_left" type="hinge" axis="0 0 1" pos="0 0 -1"/>
                
                <!-- Adding side-mounted wheel to front-left stalk -->
                <body name="wheel_front_left" pos="0 0 -1" euler='0 -90 0'>
                    <geom type="cylinder" size="0.1 0.05 0" rgba="0.5 0.5 0.5 1"/>
                    <joint name="wheel_hinge_front_left" type="hinge" axis="0 0 1" pos="0 0 0"/>
                </body>
            </body>
            
            <!-- Front-right stalk -->
            <body name="stalk_front_right" pos="1 -1.5 -0.8">
                <geom type="cylinder" size="0.05 1 0" rgba="0.5 0.5 0.5 1"/>
                <joint name="hinge_front_right" type="hinge" axis="0 0 1" pos="0 0 1"/>
                
                <!-- Adding side-mounted wheel to front-right stalk -->
                <body name="wheel_front_right" pos="0 0 -1" euler='0 -90 0'>
                    <geom type="cylinder" size="0.1 0.05 0" rgba="0.5 0.5 0.5 1"/>
                    <joint name="wheel_hinge_front_right" type="hinge" axis="0 0 1" pos="0 0 0"/>
                </body>
            </body>
            
            <!-- Back-left stalk -->
            <body name="stalk_back_left" pos="-1 1.5 -0.8">
                <geom type="cylinder" size="0.05 1 0" rgba="0.5 0.5 0.5 1"/>
                <joint name="hinge_back_left" type="hinge" axis="0 0 1" pos="0 0 -1"/>
                
                <!-- Adding side-mounted wheel to back-left stalk -->
                <body name="wheel_back_left" pos="0 0 -1" euler='0 -90 0'>
                    <geom type="cylinder" size="0.1 0.05 0" rgba="0.5 0.5 0.5 1"/>
                    <joint name="wheel_hinge_back_left" type="hinge" axis="0 0 1" pos="0 0 0"/>
                </body>
            </body>
            
            <!-- Back-right stalk -->
            <body name="stalk_back_right" pos="1 1.5 -0.8">
                <geom type="cylinder" size="0.05 1 0" rgba="0.5 0.5 0.5 1"/>
                <joint name="hinge_back_right" type="hinge" axis="0 0 1" pos="0 0 1"/>
                
                <!-- Adding side-mounted wheel to back-right stalk -->
                <body name="wheel_back_right" pos="0 0 -1" euler='0 -90 0'>
                    <geom type="cylinder" size="0.1 0.05 0" rgba="0.5 0.5 0.5 1"/>
                    <joint name="wheel_hinge_back_right" type="hinge" axis="0 0 1" pos="0 0 0"/>
                </body>
            </body>
        </body>
    </worldbody>
    
    <actuator>
        <!-- Actuators for wheel velocities with kv parameter -->
        <velocity joint="hinge_front_left" ctrlrange="-10 10" kv="100"/>
        <velocity joint="hinge_front_right" ctrlrange="-10 10" kv="100"/>
        <velocity joint="hinge_back_left" ctrlrange="-10 10" kv="100"/>
        <velocity joint="hinge_back_right" ctrlrange="-10 10" kv="100"/>
        <velocity joint="wheel_hinge_front_left" ctrlrange="-10 10" kv="100"/>
        <velocity joint="wheel_hinge_front_right" ctrlrange="-10 10" kv="100"/>
        <velocity joint="wheel_hinge_back_left" ctrlrange="-10 10" kv="100"/>
        <velocity joint="wheel_hinge_back_right" ctrlrange="-10 10" kv="100"/>
    </actuator>
</mujoco>
